Workbook

Sheet Assumptions
B1: FDRE Bid Financial Model — Assumptions
B2: NHPC FDRE Tranche-II · 200 MW · Rajasthan portfolio · All cells in BLUE are inputs; YELLOW cells are the solver levers.
B4: LEGEND & HOW TO USE
B5: Blue text = hardcoded input · Black = formula · Green = link to another sheet · Yellow fill = key lever.
B6: To re-derive the bid tariff after changing any assumption: Data ▸ What-If Analysis ▸ Goal Seek —
B7: set 'Financial Model'!C68 (Equity IRR) to 0.14 by changing Assumptions!C11 (Bid tariff).
B8: Then verify 'Financial Model'!C70 Min DSCR ≥ 1.10 (if it binds instead, Goal Seek on C70).
B10: A. OPTIMIZED BID CONFIGURATION (optimizer output — engine run, seed 42)
B11: Solar capacity (AC) | C11: 288.8 | D11: MW | E11: Optimizer result
B12: Wind capacity | C12: 40.9 | D12: MW | E12: Optimizer result
B13: BESS power | C13: 180 | D13: MW | E13: Optimizer result
B14: BESS energy | C14: 540 | D14: MWh | E14: Optimizer result
B15: Contracted (bid) capacity | C15: 200 | D15: MW | E15: Selected bid capacity
B16: Bid tariff (levelized) | C16: 5.9113 | D16: Rs/kWh | E16: REQUIRED TARIFF at declared-value delivery (CUF 40%, availability 90%): lowest tariff meeting IRR & DSCR targets — re-derive via Goal Seek (see legend)
B18: B. TENDER RULES (NHPC FDRE Tranche-II RfS)
B19: Declared annual CUF | C19: 0.4 | E19: RfS: bid declaration, min 40%
B20: Annual CUF lower tolerance | C20: 0.15 | E20: RfS: -15% on declared CUF
B21: Annual CUF upper multiplier | C21: 1.1 | D21: x | E21: RfS: NHPC offtake capped at +10%
B22: PPA offtake target (x declared CUF) | C22: 1 | D22: x | E22: SCENARIO LEVER: 1.00 = deliver at declared CUF (this case); 1.10 = deliver at the +10% offtake cap (gives Rs 5.58)
B23: Hours per year (CUF convention) | C23: 8766 | D23: h | E23: RfS LD illustration uses 8,766 h
B24: Peak availability floor (monthly) | C24: 0.9 | E24: RfS: 90% of contracted capacity in peak hours
B25: Peak hours per day | C25: 4 | D25: h | E25: 2 morning (05-10) + 2 evening (18-23), buyer-scheduled
B26: Liquidated damages multiplier | C26: 1.5 | D26: x tariff | E26: Applies to monthly-peak and annual-CUF shortfall
B27: PSM charge | C27: 0.02 | D27: Rs/kWh | E27: Netted from tariff in revenue
B28: PPA term | C28: 25 | D28: years
B30: C. RESOURCE & DELIVERED YIELD
B31: Solar net CUF (P50, base) | C31: 0.275 | E31: PVsyst — TOPCon bifacial, 1.5 DC/AC
B32: Wind net CUF (P50, base) | C32: 0.34 | E32: Project configuration; measured Bikaner data
B33: Measured-yield calibration factor | C33: 1.191142 | D33: x | E33: Calibrates synthetic base CUFs to the measured-trace optimizer run that produced the bid (engine seed 42). Change only with new yield studies.
B34: Delivery efficiency to POI | C34: 0.9 | E34: BESS cycling losses + spill in firming the peak blocks
B35: Solar degradation | C35: 0.005 | D35: /yr
B36: Wind degradation | C36: 0.002 | D36: /yr
B37: Merchant capture of surplus | C37: 0.6 | E37: Curtailment haircut and solar-hour price factor on surplus sales
B39: D. CAPEX UNIT RATES (Rs cr)
B40: Solar EPC | C40: 3.1 | D40: cr/MWac | E40: Project configuration
B41: Wind EPC | C41: 6.5 | D41: cr/MW
B42: BESS energy | C42: 1.1 | D42: cr/MWh
B43: BESS PCS | C43: 0.3 | D43: cr/MW
B44: Land & development — lump sum | C44: 90 | D44: cr | E44: Project configuration
B45: Land — solar | C45: 0.45 | D45: cr/MWac
...

Sheet Capex
B1: Capex Build-Up & Financing (Rs cr)
B3: Component | C3: Rs cr | D3: Basis | F3: IDC schedule
B4: Solar EPC | C4: =Assumptions!$C$11*Assumptions!$C$40 -> 895.28 | D4: Solar MW x EPC rate | F4: Month | G4: Debt drawn (cum) | H4: Interest
B5: Wind EPC | C5: =Assumptions!$C$12*Assumptions!$C$41 -> 265.85 | D5: Wind MW x EPC rate | F5: 1 | G5: =0+$C$19*Assumptions!$C$74/12 -> 76.095228 | H5: =G5*$C$18 -> 0.53377847
B6: BESS energy | C6: =Assumptions!$C$14*Assumptions!$C$42 -> 594 | D6: MWh x rate | F6: 2 | G6: =G5+$C$19*Assumptions!$C$74/12 -> 152.19046 | H6: =G6*$C$18 -> 1.0675569
B7: BESS PCS | C7: =Assumptions!$C$13*Assumptions!$C$43 -> 54 | D7: MW x rate | F7: 3 | G7: =G6+$C$19*Assumptions!$C$74/12 -> 228.28569 | H7: =G7*$C$18 -> 1.6013354
B8: Land & development | C8: =Assumptions!$C$44+Assumptions!$C$11*Assumptions!$C$45+Assumptions!$C$12*Assumptions!$C$46+Assumptions!$C$14*Assumptions!$C$47 -> 234.032 | D8: Lump + per-asset land | F8: 4 | G8: =G7+$C$19*Assumptions!$C$74/12 -> 304.38091 | H8: =G8*$C$18 -> 2.1351139
B9: Transmission & connectivity | C9: =Assumptions!$C$48+C16*Assumptions!$C$49 -> 460 | D9: Lump + evacuation MW x rate | F9: 5 | G9: =G8+$C$19*Assumptions!$C$74/12 -> 380.47614 | H9: =G9*$C$18 -> 2.6688924
B10: Owner's costs | C10: =Assumptions!$C$51+(Assumptions!$C$11+Assumptions!$C$12+Assumptions!$C$13)*Assumptions!$C$52 -> 121.164 | D10: Lump + all-asset MW x rate | F10: 6 | G10: =G9+$C$19*Assumptions!$C$74/12 -> 456.57137 | H10: =G10*$C$18 -> 3.2026708
B11: Success charge | C11: =Assumptions!$C$15*Assumptions!$C$53*1.18/100 -> 2.36 | D11: Contracted MW x 1 lakh x GST | F11: 7 | G11: =G10+$C$19*Assumptions!$C$74/12 -> 532.6666 | H11: =G11*$C$18 -> 3.7364493
B12: Processing fee | C12: =Assumptions!$C$54*1.18/100 -> 0.118 | D12: Slab fee x GST | F12: 8 | G12: =G11+$C$19*Assumptions!$C$74/12 -> 608.76183 | H12: =G12*$C$18 -> 4.2702278
B13: Base capex | C13: =SUM(C4:C12) -> 2626.804 | F13: 9 | G13: =G12+$C$19*Assumptions!$C$74/12 -> 684.85706 | H13: =G13*$C$18 -> 4.8040062
B14: Contingency | C14: =C13*Assumptions!$C$55 -> 78.80412 | F14: 10 | G14: =G13+$C$19*Assumptions!$C$74/12 -> 760.95228 | H14: =G14*$C$18 -> 5.3377847
B15: HARD CAPEX | C15: =C13+C14 -> 2705.6081 | F15: 11 | G15: =G14+$C$19*Assumptions!$C$74/12 -> 837.04751 | H15: =G15*$C$18 -> 5.8715632
B16: Evacuation basis (MW) | C16: =MIN(MAX(Assumptions!$C$15,Assumptions!$C$11+Assumptions!$C$12,Assumptions!$C$13),Assumptions!$C$50) -> 280 | D16: min(max(contracted, RE MW, BESS MW), interconnection) | F16: 12 | G16: =G15+$C$19*Assumptions!$C$74/12 -> 913.14274 | H16: =G16*$C$18 -> 6.4053417
F17: 13 | G17: =G16+$C$19*Assumptions!$C$75/12 -> 1006.148 | H17: =G17*$C$18 -> 7.0577376
B18: Monthly interest rate | C18: =(1+Assumptions!$C$70)^(1/12)-1 -> 0.0070146116 | F18: 14 | G18: =G17+$C$19*Assumptions!$C$75/12 -> 1099.1533 | H18: =G18*$C$18 -> 7.7101335
B19: Debt base for IDC (hard x debt%) | C19: =C15*Assumptions!$C$69 -> 2029.2061 | F19: 15 | G19: =G18+$C$19*Assumptions!$C$75/12 -> 1192.1586 | H19: =G19*$C$18 -> 8.3625294
B20: IDC (capitalized) | C20: =SUM(H5:H28) -> 169.3857 | F20: 16 | G20: =G19+$C$19*Assumptions!$C$75/12 -> 1285.1639 | H20: =G20*$C$18 -> 9.0149253
B21: TOTAL PROJECT COST | C21: =C15+C20 -> 2874.9938 | F21: 17 | G21: =G20+$C$19*Assumptions!$C$75/12 -> 1378.1691 | H21: =G21*$C$18 -> 9.6673212
B22: Debt | C22: =C21*Assumptions!$C$69 -> 2156.2454 | F22: 18 | G22: =G21+$C$19*Assumptions!$C$75/12 -> 1471.1744 | H22: =G22*$C$18 -> 10.319717
B23: Equity | C23: =C21-C22 -> 718.74846 | F23: 19 | G23: =G22+$C$19*Assumptions!$C$75/12 -> 1564.1797 | H23: =G23*$C$18 -> 10.972113
F24: 20 | G24: =G23+$C$19*Assumptions!$C$75/12 -> 1657.185 | H24: =G24*$C$18 -> 11.624509
B25: EMD (capped Rs 10 cr) | C25: =MIN(0.0928*Assumptions!$C$11+0.1264*Assumptions!$C$12+0.1464*Assumptions!$C$13,10) -> 10 | D25: Rs 9.28/12.64/14.64 lakh per MW (solar/wind/ESS) | F25: 21 | G25: =G24+$C$19*Assumptions!$C$75/12 -> 1750.1903 | H25: =G25*$C$18 -> 12.276905
B26: PBG | C26: =0.232*Assumptions!$C$11+0.316*Assumptions!$C$12+0.366*Assumptions!$C$13 -> 145.806 | D26: Rs 23.20/31.60/36.60 lakh per MW | F26: 22 | G26: =G25+$C$19*Assumptions!$C$75/12 -> 1843.1955 | H26: =G26*$C$18 -> 12.929301
F27: 23 | G27: =G26+$C$19*Assumptions!$C$75/12 -> 1936.2008 | H27: =G27*$C$18 -> 13.581697
B28: BESS augmentation capex (year 11) | C28: =Assumptions!$C$14*Assumptions!$C$91*Assumptions!$C$92 -> 405 | F28: 24 | G28: =G27+$C$19*Assumptions!$C$75/12 -> 2029.2061 | H28: =G28*$C$18 -> 14.234093
F31: CHECK: debt fully repaid by yr-18 (closing balance, cr) | G31: ='Financial Model'!T51 -> 0
F32: Goal Seek this to 0 by changing Assumptions sculpting DSCR if assumptions change.

Sheet Dispatch 25Y
B1: 25-Year Dispatch & Annual Compliance (MWh)
G2: PPA cap =
B3: Year | C3: Solar gen | D3: Wind gen | E3: RE total | F3: Delivered at POI | G3: PPA target | H3: PPA energy | I3: Annual CUF | J3: Surplus | K3: Merchant sold | L3: CUF floor ok | M3: CUF cap ok | N3: Spill
B4: 1 | C4: =Assumptions!$C$11*Assumptions!$C$23*Assumptions!$C$31*Assumptions!$C$33*(1-Assumptions!$C$35)^(B4-1) -> 829267.96 | D4: =Assumptions!$C$12*Assumptions!$C$23*Assumptions!$C$32*Assumptions!$C$33*(1-Assumptions!$C$36)^(B4-1) -> 145200.21 | E4: =C4+D4 -> 974468.17 | F4: =E4*Assumptions!$C$34 -> 877021.35 | G4: =Assumptions!$C$19*Assumptions!$C$22*Assumptions!$C$15*Assumptions!$C$23 -> 701280 | H4: =MIN(F4,G4) -> 701280 | I4: =H4/(Assumptions!$C$15*Assumptions!$C$23) -> 0.4 | J4: =F4-H4 -> 175741.35 | K4: =J4*Assumptions!$C$37 -> 105444.81 | L4: =IF(I4>=Assumptions!$C$19*(1-Assumptions!$C$20),"PASS","FAIL") -> PASS | M4: =IF(I4<=Assumptions!$C$19*Assumptions!$C$21+0.0000001,"PASS","FAIL") -> PASS | N4: =J4-K4 -> 70296.54
B5: 2 | C5: =Assumptions!$C$11*Assumptions!$C$23*Assumptions!$C$31*Assumptions!$C$33*(1-Assumptions!$C$35)^(B5-1) -> 825121.62 | D5: =Assumptions!$C$12*Assumptions!$C$23*Assumptions!$C$32*Assumptions!$C$33*(1-Assumptions!$C$36)^(B5-1) -> 144909.8 | E5: =C5+D5 -> 970031.43 | F5: =E5*Assumptions!$C$34 -> 873028.28 | G5: =Assumptions!$C$19*Assumptions!$C$22*Assumptions!$C$15*Assumptions!$C$23 -> 701280 | H5: =MIN(F5,G5) -> 701280 | I5: =H5/(Assumptions!$C$15*Assumptions!$C$23) -> 0.4 | J5: =F5-H5 -> 171748.28 | K5: =J5*Assumptions!$C$37 -> 103048.97 | L5: =IF(I5>=Assumptions!$C$19*(1-Assumptions!$C$20),"PASS","FAIL") -> PASS | M5: =IF(I5<=Assumptions!$C$19*Assumptions!$C$21+0.0000001,"PASS","FAIL") -> PASS | N5: =J5-K5 -> 68699.314
B6: 3 | C6: =Assumptions!$C$11*Assumptions!$C$23*Assumptions!$C$31*Assumptions!$C$33*(1-Assumptions!$C$35)^(B6-1) -> 820996.01 | D6: =Assumptions!$C$12*Assumptions!$C$23*Assumptions!$C$32*Assumptions!$C$33*(1-Assumptions!$C$36)^(B6-1) -> 144619.99 | E6: =C6+D6 -> 965616 | F6: =E6*Assumptions!$C$34 -> 869054.4 | G6: =Assumptions!$C$19*Assumptions!$C$22*Assumptions!$C$15*Assumptions!$C$23 -> 701280 | H6: =MIN(F6,G6) -> 701280 | I6: =H6/(Assumptions!$C$15*Assumptions!$C$23) -> 0.4 | J6: =F6-H6 -> 167774.4 | K6: =J6*Assumptions!$C$37 -> 100664.64 | L6: =IF(I6>=Assumptions!$C$19*(1-Assumptions!$C$20),"PASS","FAIL") -> PASS | M6: =IF(I6<=Assumptions!$C$19*Assumptions!$C$21+0.0000001,"PASS","FAIL") -> PASS | N6: =J6-K6 -> 67109.76
B7: 4 | C7: =Assumptions!$C$11*Assumptions!$C$23*Assumptions!$C$31*Assumptions!$C$33*(1-Assumptions!$C$35)^(B7-1) -> 816891.03 | D7: =Assumptions!$C$12*Assumptions!$C$23*Assumptions!$C$32*Assumptions!$C$33*(1-Assumptions!$C$36)^(B7-1) -> 144330.75 | E7: =C7+D7 -> 961221.78 | F7: =E7*Assumptions!$C$34 -> 865099.6 | G7: =Assumptions!$C$19*Assumptions!$C$22*Assumptions!$C$15*Assumptions!$C$23 -> 701280 | H7: =MIN(F7,G7) -> 701280 | I7: =H7/(Assumptions!$C$15*Assumptions!$C$23) -> 0.4 | J7: =F7-H7 -> 163819.6 | K7: =J7*Assumptions!$C$37 -> 98291.761 | L7: =IF(I7>=Assumptions!$C$19*(1-Assumptions!$C$20),"PASS","FAIL") -> PASS | M7: =IF(I7<=Assumptions!$C$19*Assumptions!$C$21+0.0000001,"PASS","FAIL") -> PASS | N7: =J7-K7 -> 65527.841
B8: 5 | C8: =Assumptions!$C$11*Assumptions!$C$23*Assumptions!$C$31*Assumptions!$C$33*(1-Assumptions!$C$35)^(B8-1) -> 812806.58 | D8: =Assumptions!$C$12*Assumptions!$C$23*Assumptions!$C$32*Assumptions!$C$33*(1-Assumptions!$C$36)^(B8-1) -> 144042.08 | E8: =C8+D8 -> 956848.66 | F8: =E8*Assumptions!$C$34 -> 861163.8 | G8: =Assumptions!$C$19*Assumptions!$C$22*Assumptions!$C$15*Assumptions!$C$23 -> 701280 | H8: =MIN(F8,G8) -> 701280 | I8: =H8/(Assumptions!$C$15*Assumptions!$C$23) -> 0.4 | J8: =F8-H8 -> 159883.8 | K8: =J8*Assumptions!$C$37 -> 95930.278 | L8: =IF(I8>=Assumptions!$C$19*(1-Assumptions!$C$20),"PASS","FAIL") -> PASS | M8: =IF(I8<=Assumptions!$C$19*Assumptions!$C$21+0.0000001,"PASS","FAIL") -> PASS | N8: =J8-K8 -> 63953.519
B9: 6 | C9: =Assumptions!$C$11*Assumptions!$C$23*Assumptions!$C$31*Assumptions!$C$33*(1-Assumptions!$C$35)^(B9-1) -> 808742.55 | D9: =Assumptions!$C$12*Assumptions!$C$23*Assumptions!$C$32*Assumptions!$C$33*(1-Assumptions!$C$36)^(B9-1) -> 143754 | E9: =C9+D9 -> 952496.55 | F9: =E9*Assumptions!$C$34 -> 857246.89 | G9: =Assumptions!$C$19*Assumptions!$C$22*Assumptions!$C$15*Assumptions!$C$23 -> 701280 | H9: =MIN(F9,G9) -> 701280 | I9: =H9/(Assumptions!$C$15*Assumptions!$C$23) -> 0.4 | J9: =F9-H9 -> 155966.89 | K9: =J9*Assumptions!$C$37 -> 93580.135 | L9: =IF(I9>=Assumptions!$C$19*(1-Assumptions!$C$20),"PASS","FAIL") -> PASS | M9: =IF(I9<=Assumptions!$C$19*Assumptions!$C$21+0.0000001,"PASS","FAIL") -> PASS | N9: =J9-K9 -> 62386.756
B10: 7 | C10: =Assumptions!$C$11*Assumptions!$C$23*Assumptions!$C$31*Assumptions!$C$33*(1-Assumptions!$C$35)^(B10-1) -> 804698.83 | D10: =Assumptions!$C$12*Assumptions!$C$23*Assumptions!$C$32*Assumptions!$C$33*(1-Assumptions!$C$36)^(B10-1) -> 143466.49 | E10: =C10+D10 -> 948165.32 | F10: =E10*Assumptions!$C$34 -> 853348.79 | G10: =Assumptions!$C$19*Assumptions!$C$22*Assumptions!$C$15*Assumptions!$C$23 -> 701280 | H10: =MIN(F10,G10) -> 701280 | I10: =H10/(Assumptions!$C$15*Assumptions!$C$23) -> 0.4 | J10: =F10-H10 -> 152068.79 | K10: =J10*Assumptions!$C$37 -> 91241.275 | L10: =IF(I10>=Assumptions!$C$19*(1-Assumptions!$C$20),"PASS","FAIL") -> PASS | M10: =IF(I10<=Assumptions!$C$19*Assumptions!$C$21+0.0000001,"PASS","FAIL") -> PASS | N10: =J10-K10 -> 60827.517
B11: 8 | C11: =Assumptions!$C$11*Assumptions!$C$23*Assumptions!$C$31*Assumptions!$C$33*(1-Assumptions!$C$35)^(B11-1) -> 800675.34 | D11: =Assumptions!$C$12*Assumptions!$C$23*Assumptions!$C$32*Assumptions!$C$33*(1-Assumptions!$C$36)^(B11-1) -> 143179.56 | E11: =C11+D11 -> 943854.9 | F11: =E11*Assumptions!$C$34 -> 849469.41 | G11: =Assumptions!$C$19*Assumptions!$C$22*Assumptions!$C$15*Assumptions!$C$23 -> 701280 | H11: =MIN(F11,G11) -> 701280 | I11: =H11/(Assumptions!$C$15*Assumptions!$C$23) -> 0.4 | J11: =F11-H11 -> 148189.41 | K11: =J11*Assumptions!$C$37 -> 88913.645 | L11: =IF(I11>=Assumptions!$C$19*(1-Assumptions!$C$20),"PASS","FAIL") -> PASS | M11: =IF(I11<=Assumptions!$C$19*Assumptions!$C$21+0.0000001,"PASS","FAIL") -> PASS | N11: =J11-K11 -> 59275.763
B12: 9 | C12: =Assumptions!$C$11*Assumptions!$C$23*Assumptions!$C$31*Assumptions!$C$33*(1-Assumptions!$C$35)^(B12-1) -> 796671.96 | D12: =Assumptions!$C$12*Assumptions!$C$23*Assumptions!$C$32*Assumptions!$C$33*(1-Assumptions!$C$36)^(B12-1) -> 142893.2 | E12: =C12+D12 -> 939565.16 | F12: =E12*Assumptions!$C$34 -> 845608.65 | G12: =Assumptions!$C$19*Assumptions!$C$22*Assumptions!$C$15*Assumptions!$C$23 -> 701280 | H12: =MIN(F12,G12) -> 701280 | I12: =H12/(Assumptions!$C$15*Assumptions!$C$23) -> 0.4 | J12: =F12-H12 -> 144328.65 | K12: =J12*Assumptions!$C$37 -> 86597.187 | L12: =IF(I12>=Assumptions!$C$19*(1-Assumptions!$C$20),"PASS","FAIL") -> PASS | M12: =IF(I12<=Assumptions!$C$19*Assumptions!$C$21+0.0000001,"PASS","FAIL") -> PASS | N12: =J12-K12 -> 57731.458
B13: 10 | C13: =Assumptions!$C$11*Assumptions!$C$23*Assumptions!$C$31*Assumptions!$C$33*(1-Assumptions!$C$35)^(B13-1) -> 792688.6 | D13: =Assumptions!$C$12*Assumptions!$C$23*Assumptions!$C$32*Assumptions!$C$33*(1-Assumptions!$C$36)^(B13-1) -> 142607.41 | E13: =C13+D13 -> 935296.02 | F13: =E13*Assumptions!$C$34 -> 841766.41 | G13: =Assumptions!$C$19*Assumptions!$C$22*Assumptions!$C$15*Assumptions!$C$23 -> 701280 | H13: =MIN(F13,G13) -> 701280 | I13: =H13/(Assumptions!$C$15*Assumptions!$C$23) -> 0.4 | J13: =F13-H13 -> 140486.41 | K13: =J13*Assumptions!$C$37 -> 84291.848 | L13: =IF(I13>=Assumptions!$C$19*(1-Assumptions!$C$20),"PASS","FAIL") -> PASS | M13: =IF(I13<=Assumptions!$C$19*Assumptions!$C$21+0.0000001,"PASS","FAIL") -> PASS | N13: =J13-K13 -> 56194.566
B14: 11 | C14: =Assumptions!$C$11*Assumptions!$C$23*Assumptions!$C$31*Assumptions!$C$33*(1-Assumptions!$C$35)^(B14-1) -> 788725.16 | D14: =Assumptions!$C$12*Assumptions!$C$23*Assumptions!$C$32*Assumptions!$C$33*(1-Assumptions!$C$36)^(B14-1) -> 142322.2 | E14: =C14+D14 -> 931047.36 | F14: =E14*Assumptions!$C$34 -> 837942.62 | G14: =Assumptions!$C$19*Assumptions!$C$22*Assumptions!$C$15*Assumptions!$C$23 -> 701280 | H14: =MIN(F14,G14) -> 701280 | I14: =H14/(Assumptions!$C$15*Assumptions!$C$23) -> 0.4 | J14: =F14-H14 -> 136662.62 | K14: =J14*Assumptions!$C$37 -> 81997.573 | L14: =IF(I14>=Assumptions!$C$19*(1-Assumptions!$C$20),"PASS","FAIL") -> PASS | M14: =IF(I14<=Assumptions!$C$19*Assumptions!$C$21+0.0000001,"PASS","FAIL") -> PASS | N14: =J14-K14 -> 54665.049
B15: 12 | C15: =Assumptions!$C$11*Assumptions!$C$23*Assumptions!$C$31*Assumptions!$C$33*(1-Assumptions!$C$35)^(B15-1) -> 784781.53 | D15: =Assumptions!$C$12*Assumptions!$C$23*Assumptions!$C$32*Assumptions!$C$33*(1-Assumptions!$C$36)^(B15-1) -> 142037.55 | E15: =C15+D15 -> 926819.09 | F15: =E15*Assumptions!$C$34 -> 834137.18 | G15: =Assumptions!$C$19*Assumptions!$C$22*Assumptions!$C$15*Assumptions!$C$23 -> 701280 | H15: =MIN(F15,G15) -> 701280 | I15: =H15/(Assumptions!$C$15*Assumptions!$C$23) -> 0.4 | J15: =F15-H15 -> 132857.18 | K15: =J15*Assumptions!$C$37 -> 79714.307 | L15: =IF(I15>=Assumptions!$C$19*(1-Assumptions!$C$20),"PASS","FAIL") -> PASS | M15: =IF(I15<=Assumptions!$C$19*Assumptions!$C$21+0.0000001,"PASS","FAIL") -> PASS | N15: =J15-K15 -> 53142.872
... B28: 25 | C28: =Assumptions!$C$11*Assumptions!$C$23*Assumptions!$C$31*Assumptions!$C$33*(1-Assumptions!$C$35)^(B28-1) -> 735273.35 | D28: =Assumptions!$C$12*Assumptions!$C$23*Assumptions!$C$32*Assumptions!$C$33*(1-Assumptions!$C$36)^(B28-1) -> 138388.57 | E28: =C28+D28 -> 873661.92 | F28: =E28*Assumptions!$C$34 -> 786295.73 | G28: =Assumptions!$C$19*Assumptions!$C$22*Assumptions!$C$15*Assumptions!$C$23 -> 701280 | H28: =MIN(F28,G28) -> 701280 | I28: =H28/(Assumptions!$C$15*Assumptions!$C$23) -> 0.4 | J28: =F28-H28 -> 85015.728 | K28: =J28*Assumptions!$C$37 -> 51009.437 | L28: =IF(I28>=Assumptions!$C$19*(1-Assumptions!$C$20),"PASS","FAIL") -> PASS | M28: =IF(I28<=Assumptions!$C$19*Assumptions!$C$21+0.0000001,"PASS","FAIL") -> PASS | N28: =J28-K28 -> 34006.291
B29: Scenario: PPA delivery held at the DECLARED CUF (40%) in all 25 years — inside the -15%/+10% band throughout. Surplus RE above the target is sold merchant at the capture factor. Set the offtake lever to 1.10 to model delivery at the +10% cap.

Sheet Monthly Y1
B1: Year-1 Monthly Dispatch & Peak Compliance
B3: Month | C3: Days | D3: Peak hours | E3: Peak obligation MWh | F3: Availability % | G3: Peak delivered MWh | H3: Floor (90%) MWh | I3: Shortfall MWh | J3: LD Rs cr | K3: Compliant | L3: PPA energy MWh | M3: Monthly CUF
B4: Jan | C4: 31 | D4: =C4*Assumptions!$C$25 -> 124 | E4: =D4*Assumptions!$C$15 -> 24800 | F4: 0.9 | G4: =E4*F4 -> 22320 | H4: =E4*Assumptions!$C$24 -> 22320 | I4: =MAX(0,H4-G4) -> 0 | J4: =I4*Assumptions!$C$26*Assumptions!$C$16/10000 -> 0 | K4: =IF(F4>=Assumptions!$C$24,"PASS","FAIL") -> PASS | L4: ='Dispatch 25Y'!H4*C4/365 -> 59560.767 | M4: =L4/(Assumptions!$C$15*C4*24) -> 0.40027397
B5: Feb | C5: 28 | D5: =C5*Assumptions!$C$25 -> 112 | E5: =D5*Assumptions!$C$15 -> 22400 | F5: 0.9 | G5: =E5*F5 -> 20160 | H5: =E5*Assumptions!$C$24 -> 20160 | I5: =MAX(0,H5-G5) -> 0 | J5: =I5*Assumptions!$C$26*Assumptions!$C$16/10000 -> 0 | K5: =IF(F5>=Assumptions!$C$24,"PASS","FAIL") -> PASS | L5: ='Dispatch 25Y'!H4*C5/365 -> 53796.822 | M5: =L5/(Assumptions!$C$15*C5*24) -> 0.40027397
B6: Mar | C6: 31 | D6: =C6*Assumptions!$C$25 -> 124 | E6: =D6*Assumptions!$C$15 -> 24800 | F6: 0.9 | G6: =E6*F6 -> 22320 | H6: =E6*Assumptions!$C$24 -> 22320 | I6: =MAX(0,H6-G6) -> 0 | J6: =I6*Assumptions!$C$26*Assumptions!$C$16/10000 -> 0 | K6: =IF(F6>=Assumptions!$C$24,"PASS","FAIL") -> PASS | L6: ='Dispatch 25Y'!H4*C6/365 -> 59560.767 | M6: =L6/(Assumptions!$C$15*C6*24) -> 0.40027397
B7: Apr | C7: 30 | D7: =C7*Assumptions!$C$25 -> 120 | E7: =D7*Assumptions!$C$15 -> 24000 | F7: 0.9 | G7: =E7*F7 -> 21600 | H7: =E7*Assumptions!$C$24 -> 21600 | I7: =MAX(0,H7-G7) -> 0 | J7: =I7*Assumptions!$C$26*Assumptions!$C$16/10000 -> 0 | K7: =IF(F7>=Assumptions!$C$24,"PASS","FAIL") -> PASS | L7: ='Dispatch 25Y'!H4*C7/365 -> 57639.452 | M7: =L7/(Assumptions!$C$15*C7*24) -> 0.40027397
B8: May | C8: 31 | D8: =C8*Assumptions!$C$25 -> 124 | E8: =D8*Assumptions!$C$15 -> 24800 | F8: 0.9 | G8: =E8*F8 -> 22320 | H8: =E8*Assumptions!$C$24 -> 22320 | I8: =MAX(0,H8-G8) -> 0 | J8: =I8*Assumptions!$C$26*Assumptions!$C$16/10000 -> 0 | K8: =IF(F8>=Assumptions!$C$24,"PASS","FAIL") -> PASS | L8: ='Dispatch 25Y'!H4*C8/365 -> 59560.767 | M8: =L8/(Assumptions!$C$15*C8*24) -> 0.40027397
B9: Jun | C9: 30 | D9: =C9*Assumptions!$C$25 -> 120 | E9: =D9*Assumptions!$C$15 -> 24000 | F9: 0.9 | G9: =E9*F9 -> 21600 | H9: =E9*Assumptions!$C$24 -> 21600 | I9: =MAX(0,H9-G9) -> 0 | J9: =I9*Assumptions!$C$26*Assumptions!$C$16/10000 -> 0 | K9: =IF(F9>=Assumptions!$C$24,"PASS","FAIL") -> PASS | L9: ='Dispatch 25Y'!H4*C9/365 -> 57639.452 | M9: =L9/(Assumptions!$C$15*C9*24) -> 0.40027397
B10: Jul | C10: 31 | D10: =C10*Assumptions!$C$25 -> 124 | E10: =D10*Assumptions!$C$15 -> 24800 | F10: 0.9 | G10: =E10*F10 -> 22320 | H10: =E10*Assumptions!$C$24 -> 22320 | I10: =MAX(0,H10-G10) -> 0 | J10: =I10*Assumptions!$C$26*Assumptions!$C$16/10000 -> 0 | K10: =IF(F10>=Assumptions!$C$24,"PASS","FAIL") -> PASS | L10: ='Dispatch 25Y'!H4*C10/365 -> 59560.767 | M10: =L10/(Assumptions!$C$15*C10*24) -> 0.40027397
B11: Aug | C11: 31 | D11: =C11*Assumptions!$C$25 -> 124 | E11: =D11*Assumptions!$C$15 -> 24800 | F11: 0.9 | G11: =E11*F11 -> 22320 | H11: =E11*Assumptions!$C$24 -> 22320 | I11: =MAX(0,H11-G11) -> 0 | J11: =I11*Assumptions!$C$26*Assumptions!$C$16/10000 -> 0 | K11: =IF(F11>=Assumptions!$C$24,"PASS","FAIL") -> PASS | L11: ='Dispatch 25Y'!H4*C11/365 -> 59560.767 | M11: =L11/(Assumptions!$C$15*C11*24) -> 0.40027397
B12: Sep | C12: 30 | D12: =C12*Assumptions!$C$25 -> 120 | E12: =D12*Assumptions!$C$15 -> 24000 | F12: 0.9 | G12: =E12*F12 -> 21600 | H12: =E12*Assumptions!$C$24 -> 21600 | I12: =MAX(0,H12-G12) -> 0 | J12: =I12*Assumptions!$C$26*Assumptions!$C$16/10000 -> 0 | K12: =IF(F12>=Assumptions!$C$24,"PASS","FAIL") -> PASS | L12: ='Dispatch 25Y'!H4*C12/365 -> 57639.452 | M12: =L12/(Assumptions!$C$15*C12*24) -> 0.40027397
B13: Oct | C13: 31 | D13: =C13*Assumptions!$C$25 -> 124 | E13: =D13*Assumptions!$C$15 -> 24800 | F13: 0.9 | G13: =E13*F13 -> 22320 | H13: =E13*Assumptions!$C$24 -> 22320 | I13: =MAX(0,H13-G13) -> 0 | J13: =I13*Assumptions!$C$26*Assumptions!$C$16/10000 -> 0 | K13: =IF(F13>=Assumptions!$C$24,"PASS","FAIL") -> PASS | L13: ='Dispatch 25Y'!H4*C13/365 -> 59560.767 | M13: =L13/(Assumptions!$C$15*C13*24) -> 0.40027397
B14: Nov | C14: 30 | D14: =C14*Assumptions!$C$25 -> 120 | E14: =D14*Assumptions!$C$15 -> 24000 | F14: 0.9 | G14: =E14*F14 -> 21600 | H14: =E14*Assumptions!$C$24 -> 21600 | I14: =MAX(0,H14-G14) -> 0 | J14: =I14*Assumptions!$C$26*Assumptions!$C$16/10000 -> 0 | K14: =IF(F14>=Assumptions!$C$24,"PASS","FAIL") -> PASS | L14: ='Dispatch 25Y'!H4*C14/365 -> 57639.452 | M14: =L14/(Assumptions!$C$15*C14*24) -> 0.40027397
B15: Dec | C15: 31 | D15: =C15*Assumptions!$C$25 -> 124 | E15: =D15*Assumptions!$C$15 -> 24800 | F15: 0.9 | G15: =E15*F15 -> 22320 | H15: =E15*Assumptions!$C$24 -> 22320 | I15: =MAX(0,H15-G15) -> 0 | J15: =I15*Assumptions!$C$26*Assumptions!$C$16/10000 -> 0 | K15: =IF(F15>=Assumptions!$C$24,"PASS","FAIL") -> PASS | L15: ='Dispatch 25Y'!H4*C15/365 -> 59560.767 | M15: =L15/(Assumptions!$C$15*C15*24) -> 0.40027397
B16: TOTAL / MIN | C16: =SUM(C4:C15) -> 365 | E16: =SUM(E4:E15) -> 292000 | F16: =MIN(F4:F15) -> 0.9 | I16: =SUM(I4:I15) -> 0 | J16: =SUM(J4:J15) -> 0 | K16: =IF(COUNTIF(K4:K15,"FAIL")=0,"ALL PASS","FAIL") -> ALL PASS | L16: =SUM(L4:L15) -> 701280
B18: Scenario: availability held at the 90% RfS floor in every month (blue inputs) — exactly compliant, zero liquidated damages. Replace with monthly dispatch output when re-running the engine.

Sheet Financial Model
B1: 25-Year Financial Model (Rs cr unless noted)
B2: Year | C2: 1 | D2: 2 | E2: 3 | F2: 4 | G2: 5 | H2: 6 | I2: 7 | J2: 8 | K2: 9 | L2: 10 | M2: 11 | N2: 12 | O2: 13 | P2: 14 | Q2: 15 | R2: 16 | S2: 17 | T2: 18 | U2: 19 | V2: 20 | W2: 21 | X2: 22 | Y2: 23 | Z2: 24 | AA2: 25
B4: ENERGY
B5: PPA energy (MWh) | C5: ='Dispatch 25Y'!H4 -> 701280 | D5: ='Dispatch 25Y'!H5 -> 701280 | E5: ='Dispatch 25Y'!H6 -> 701280 | F5: ='Dispatch 25Y'!H7 -> 701280 | G5: ='Dispatch 25Y'!H8 -> 701280 | H5: ='Dispatch 25Y'!H9 -> 701280 | I5: ='Dispatch 25Y'!H10 -> 701280 | J5: ='Dispatch 25Y'!H11 -> 701280 | K5: ='Dispatch 25Y'!H12 -> 701280 | L5: ='Dispatch 25Y'!H13 -> 701280 | M5: ='Dispatch 25Y'!H14 -> 701280 | N5: ='Dispatch 25Y'!H15 -> 701280 | O5: ='Dispatch 25Y'!H16 -> 701280 | P5: ='Dispatch 25Y'!H17 -> 701280 | Q5: ='Dispatch 25Y'!H18 -> 701280 | R5: ='Dispatch 25Y'!H19 -> 701280 | S5: ='Dispatch 25Y'!H20 -> 701280 | T5: ='Dispatch 25Y'!H21 -> 701280 | U5: ='Dispatch 25Y'!H22 -> 701280 | V5: ='Dispatch 25Y'!H23 -> 701280 | W5: ='Dispatch 25Y'!H24 -> 701280 | X5: ='Dispatch 25Y'!H25 -> 701280 | Y5: ='Dispatch 25Y'!H26 -> 701280 | Z5: ='Dispatch 25Y'!H27 -> 701280 | AA5: ='Dispatch 25Y'!H28 -> 701280
B6: Merchant energy (MWh) | C6: ='Dispatch 25Y'!K4 -> 105444.81 | D6: ='Dispatch 25Y'!K5 -> 103048.97 | E6: ='Dispatch 25Y'!K6 -> 100664.64 | F6: ='Dispatch 25Y'!K7 -> 98291.761 | G6: ='Dispatch 25Y'!K8 -> 95930.278 | H6: ='Dispatch 25Y'!K9 -> 93580.135 | I6: ='Dispatch 25Y'!K10 -> 91241.275 | J6: ='Dispatch 25Y'!K11 -> 88913.645 | K6: ='Dispatch 25Y'!K12 -> 86597.187 | L6: ='Dispatch 25Y'!K13 -> 84291.848 | M6: ='Dispatch 25Y'!K14 -> 81997.573 | N6: ='Dispatch 25Y'!K15 -> 79714.307 | O6: ='Dispatch 25Y'!K16 -> 77441.997 | P6: ='Dispatch 25Y'!K17 -> 75180.587 | Q6: ='Dispatch 25Y'!K18 -> 72930.026 | R6: ='Dispatch 25Y'!K19 -> 70690.259 | S6: ='Dispatch 25Y'!K20 -> 68461.233 | T6: ='Dispatch 25Y'!K21 -> 66242.896 | U6: ='Dispatch 25Y'!K22 -> 64035.195 | V6: ='Dispatch 25Y'!K23 -> 61838.077 | W6: ='Dispatch 25Y'!K24 -> 59651.492 | X6: ='Dispatch 25Y'!K25 -> 57475.386 | Y6: ='Dispatch 25Y'!K26 -> 55309.709 | Z6: ='Dispatch 25Y'!K27 -> 53154.41 | AA6: ='Dispatch 25Y'!K28 -> 51009.437
B8: REVENUE
B9: Net PPA tariff (Rs/kWh, tariff - PSM) | C9: =Assumptions!$C$16-Assumptions!$C$27 -> 5.8913 | D9: =Assumptions!$C$16-Assumptions!$C$27 -> 5.8913 | E9: =Assumptions!$C$16-Assumptions!$C$27 -> 5.8913 | F9: =Assumptions!$C$16-Assumptions!$C$27 -> 5.8913 | G9: =Assumptions!$C$16-Assumptions!$C$27 -> 5.8913 | H9: =Assumptions!$C$16-Assumptions!$C$27 -> 5.8913 | I9: =Assumptions!$C$16-Assumptions!$C$27 -> 5.8913 | J9: =Assumptions!$C$16-Assumptions!$C$27 -> 5.8913 | ... AA9: =Assumptions!$C$16-Assumptions!$C$27 -> 5.8913
B10: PPA revenue | C10: =C5*C9/10000 -> 413.14509 | D10: =D5*D9/10000 -> 413.14509 | E10: =E5*E9/10000 -> 413.14509 | F10: =F5*F9/10000 -> 413.14509 | G10: =G5*G9/10000 -> 413.14509 | H10: =H5*H9/10000 -> 413.14509 | I10: =I5*I9/10000 -> 413.14509 | J10: =J5*J9/10000 -> 413.14509 | ... AA10: =AA5*AA9/10000 -> 413.14509
B11: Merchant price (Rs/kWh) | C11: =Assumptions!$C$93*(1+Assumptions!$C$94)^(C2-1) -> 3.25 | D11: =Assumptions!$C$93*(1+Assumptions!$C$94)^(D2-1) -> 3.315 | E11: =Assumptions!$C$93*(1+Assumptions!$C$94)^(E2-1) -> 3.3813 | F11: =Assumptions!$C$93*(1+Assumptions!$C$94)^(F2-1) -> 3.448926 | G11: =Assumptions!$C$93*(1+Assumptions!$C$94)^(G2-1) -> 3.5179045 | H11: =Assumptions!$C$93*(1+Assumptions!$C$94)^(H2-1) -> 3.5882626 | I11: =Assumptions!$C$93*(1+Assumptions!$C$94)^(I2-1) -> 3.6600279 | J11: =Assumptions!$C$93*(1+Assumptions!$C$94)^(J2-1) -> 3.7332284 | ... AA11: =Assumptions!$C$93*(1+Assumptions!$C$94)^(AA2-1) -> 5.2274211
B12: Merchant revenue | C12: =C6*C11/10000 -> 34.269563 | D12: =D6*D11/10000 -> 34.160734 | E12: =E6*E11/10000 -> 34.037735 | F12: =F6*F11/10000 -> 33.900101 | G12: =G6*G11/10000 -> 33.747356 | H12: =H6*H11/10000 -> 33.57901 | I12: =I6*I11/10000 -> 33.394561 | J12: =J6*J11/10000 -> 33.193495 | ... AA12: =AA6*AA11/10000 -> 26.66478
B13: Total revenue | C13: =C10+C12 -> 447.41465 | D13: =D10+D12 -> 447.30582 | E13: =E10+E12 -> 447.18282 | F13: =F10+F12 -> 447.04519 | G13: =G10+G12 -> 446.89244 | H13: =H10+H12 -> 446.7241 | I13: =I10+I12 -> 446.53965 | J13: =J10+J12 -> 446.33858 | ... AA13: =AA10+AA12 -> 439.80987
B15: OPERATING EXPENSES
B16: Generation + BESS O&M (escalated) | C16: =((Assumptions!$C$11*Assumptions!$C$58+Assumptions!$C$12*Assumptions!$C$59+Assumptions!$C$14*Assumptions!$C$60)/100)*(1+Assumptions!$C$65)^(C2-1) -> 26.863 | D16: =((Assumptions!$C$11*Assumptions!$C$58+Assumptions!$C$12*Assumptions!$C$59+Assumptions!$C$14*Assumptions!$C$60)/100)*(1+Assumptions!$C$65)^(D2-1) -> 27.803205 | E16: =((Assumptions!$C$11*Assumptions!$C$58+Assumptions!$C$12*Assumptions!$C$59+Assumptions!$C$14*Assumptions!$C$60)/100)*(1+Assumptions!$C$65)^(E2-1) -> 28.776317 | F16: =((Assumptions!$C$11*Assumptions!$C$58+Assumptions!$C$12*Assumptions!$C$59+Assumptions!$C$14*Assumptions!$C$60)/100)*(1+Assumptions!$C$65)^(F2-1) -> 29.783488 | G16: =((Assumptions!$C$11*Assumptions!$C$58+Assumptions!$C$12*Assumptions!$C$59+Assumptions!$C$14*Assumptions!$C$60)/100)*(1+Assumptions!$C$65)^(G2-1) -> 30.82591 | H16: =((Assumptions!$C$11*Assumptions!$C$58+Assumptions!$C$12*Assumptions!$C$59+Assumptions!$C$14*Assumptions!$C$60)/100)*(1+Assumptions!$C$65)^(H2-1) -> 31.904817 | I16: =((Assumptions!$C$11*Assumptions!$C$58+Assumptions!$C$12*Assumptions!$C$59+Assumptions!$C$14*Assumptions!$C$60)/100)*(1+Assumptions!$C$65)^(I2-1) -> 33.021486 | J16: =((Assumptions!$C$11*Assumptions!$C$58+Assumptions!$C$12*Assumptions!$C$59+Assumptions!$C$14*Assumptions!$C$60)/100)*(1+Assumptions!$C$65)^(J2-1) -> 34.177238 | ... AA16: =((Assumptions!$C$11*Assumptions!$C$58+Assumptions!$C$12*Assumptions!$C$59+Assumptions!$C$14*Assumptions!$C$60)/100)*(1+Assumptions!$C$65)^(AA2-1) -> 61.337053
B17: Admin (escalated) | C17: =(Assumptions!$C$61+(Assumptions!$C$11+Assumptions!$C$12+Assumptions!$C$13)*Assumptions!$C$62/100)*(1+Assumptions!$C$65)^(C2-1) -> 8.82275 | D17: =(Assumptions!$C$61+(Assumptions!$C$11+Assumptions!$C$12+Assumptions!$C$13)*Assumptions!$C$62/100)*(1+Assumptions!$C$65)^(D2-1) -> 9.1315462 | E17: =(Assumptions!$C$61+(Assumptions!$C$11+Assumptions!$C$12+Assumptions!$C$13)*Assumptions!$C$62/100)*(1+Assumptions!$C$65)^(E2-1) -> 9.4511504 | F17: =(Assumptions!$C$61+(Assumptions!$C$11+Assumptions!$C$12+Assumptions!$C$13)*Assumptions!$C$62/100)*(1+Assumptions!$C$65)^(F2-1) -> 9.7819406 | G17: =(Assumptions!$C$61+(Assumptions!$C$11+Assumptions!$C$12+Assumptions!$C$13)*Assumptions!$C$62/100)*(1+Assumptions!$C$65)^(G2-1) -> 10.124309 | H17: =(Assumptions!$C$61+(Assumptions!$C$11+Assumptions!$C$12+Assumptions!$C$13)*Assumptions!$C$62/100)*(1+Assumptions!$C$65)^(H2-1) -> 10.478659 | I17: =(Assumptions!$C$61+(Assumptions!$C$11+Assumptions!$C$12+Assumptions!$C$13)*Assumptions!$C$62/100)*(1+Assumptions!$C$65)^(I2-1) -> 10.845412 | J17: =(Assumptions!$C$61+(Assumptions!$C$11+Assumptions!$C$12+Assumptions!$C$13)*Assumptions!$C$62/100)*(1+Assumptions!$C$65)^(J2-1) -> 11.225002 | ... AA17: =(Assumptions!$C$61+(Assumptions!$C$11+Assumptions!$C$12+Assumptions!$C$13)*Assumptions!$C$62/100)*(1+Assumptions!$C$65)^(AA2-1) -> 20.145236
B18: Transmission O&M (escalated) | C18: =Capex!$C$16*Assumptions!$C$63/100*(1+Assumptions!$C$65)^(C2-1) -> 5.6 | D18: =Capex!$C$16*Assumptions!$C$63/100*(1+Assumptions!$C$65)^(D2-1) -> 5.796 | E18: =Capex!$C$16*Assumptions!$C$63/100*(1+Assumptions!$C$65)^(E2-1) -> 5.99886 | F18: =Capex!$C$16*Assumptions!$C$63/100*(1+Assumptions!$C$65)^(F2-1) -> 6.2088201 | G18: =Capex!$C$16*Assumptions!$C$63/100*(1+Assumptions!$C$65)^(G2-1) -> 6.4261288 | H18: =Capex!$C$16*Assumptions!$C$63/100*(1+Assumptions!$C$65)^(H2-1) -> 6.6510433 | I18: =Capex!$C$16*Assumptions!$C$63/100*(1+Assumptions!$C$65)^(I2-1) -> 6.8838298 | J18: =Capex!$C$16*Assumptions!$C$63/100*(1+Assumptions!$C$65)^(J2-1) -> 7.1247639 | ... AA18: =Capex!$C$16*Assumptions!$C$63/100*(1+Assumptions!$C$65)^(AA2-1) -> 12.78664
B19: Insurance (on hard capex) | C19: =Capex!$C$15*Assumptions!$C$64 -> 9.4696284 | D19: =Capex!$C$15*Assumptions!$C$64 -> 9.4696284 | E19: =Capex!$C$15*Assumptions!$C$64 -> 9.4696284 | F19: =Capex!$C$15*Assumptions!$C$64 -> 9.4696284 | G19: =Capex!$C$15*Assumptions!$C$64 -> 9.4696284 | H19: =Capex!$C$15*Assumptions!$C$64 -> 9.4696284 | I19: =Capex!$C$15*Assumptions!$C$64 -> 9.4696284 | J19: =Capex!$C$15*Assumptions!$C$64 -> 9.4696284 | ... AA19: =Capex!$C$15*Assumptions!$C$64 -> 9.4696284
B20: Working-capital interest | C20: =MAX(C13,0)*Assumptions!$C$79/365*Assumptions!$C$80 -> 6.9870233 | D20: =MAX(D13,0)*Assumptions!$C$79/365*Assumptions!$C$80 -> 6.9853238 | E20: =MAX(E13,0)*Assumptions!$C$79/365*Assumptions!$C$80 -> 6.983403 | F20: =MAX(F13,0)*Assumptions!$C$79/365*Assumptions!$C$80 -> 6.9812536 | G20: =MAX(G13,0)*Assumptions!$C$79/365*Assumptions!$C$80 -> 6.9788683 | H20: =MAX(H13,0)*Assumptions!$C$79/365*Assumptions!$C$80 -> 6.9762393 | I20: =MAX(I13,0)*Assumptions!$C$79/365*Assumptions!$C$80 -> 6.9733589 | J20: =MAX(J13,0)*Assumptions!$C$79/365*Assumptions!$C$80 -> 6.9702189 | ... AA20: =MAX(AA13,0)*Assumptions!$C$79/365*Assumptions!$C$80 -> 6.8682637
B21: Transmission losses (on PPA revenue) | C21: =C10*Assumptions!$C$66 -> 2.0657254 | D21: =D10*Assumptions!$C$66 -> 2.0657254 | E21: =E10*Assumptions!$C$66 -> 2.0657254 | F21: =F10*Assumptions!$C$66 -> 2.0657254 | G21: =G10*Assumptions!$C$66 -> 2.0657254 | H21: =H10*Assumptions!$C$66 -> 2.0657254 | I21: =I10*Assumptions!$C$66 -> 2.0657254 | J21: =J10*Assumptions!$C$66 -> 2.0657254 | ... AA21: =AA10*Assumptions!$C$66 -> 2.0657254
B22: Total opex | C22: =SUM(C16:C21) -> 59.808127 | D22: =SUM(D16:D21) -> 61.251429 | E22: =SUM(E16:E21) -> 62.745084 | F22: =SUM(F16:F21) -> 64.290856 | G22: =SUM(G16:G21) -> 65.89057 | H22: =SUM(H16:H21) -> 67.546113 | I22: =SUM(I16:I21) -> 69.259441 | J22: =SUM(J16:J21) -> 71.032576 | ... AA22: =SUM(AA16:AA21) -> 112.67255
B23: EBITDA | C23: =C13-C22 -> 387.60652 | D23: =D13-D22 -> 386.05439 | E23: =E13-E22 -> 384.43774 | F23: =F13-F22 -> 382.75433 | G23: =G13-G22 -> 381.00187 | H23: =H13-H22 -> 379.17798 | I23: =I13-I22 -> 377.28021 | J23: =J13-J22 -> 375.306 | ... AA23: =AA13-AA22 -> 327.13732
B25: TAX COMPUTATION (Sec 115BAA, WDV + loss carry-forward)
B26: WDV block — opening | C26: =Capex!$C$21*Assumptions!$C$85 -> 2731.2441 | D26: =C29 -> 1638.7465 | E26: =D29 -> 983.24789 | F26: =E29 -> 589.94873 | G26: =F29 -> 353.96924 | H26: =G29 -> 212.38154 | I26: =H29 -> 127.42893 | J26: =I29 -> 76.457356 | K26: =J29 -> 45.874413 | ... AA26: =Z29 -> 0.3144478
B27: Addition (augmentation x eligible) | C27: =IF(C2=Assumptions!$C$90,Capex!$C$28*Assumptions!$C$85,0) -> 0 | D27: =IF(D2=Assumptions!$C$90,Capex!$C$28*Assumptions!$C$85,0) -> 0 | E27: =IF(E2=Assumptions!$C$90,Capex!$C$28*Assumptions!$C$85,0) -> 0 | F27: =IF(F2=Assumptions!$C$90,Capex!$C$28*Assumptions!$C$85,0) -> 0 | G27: =IF(G2=Assumptions!$C$90,Capex!$C$28*Assumptions!$C$85,0) -> 0 | H27: =IF(H2=Assumptions!$C$90,Capex!$C$28*Assumptions!$C$85,0) -> 0 | I27: =IF(I2=Assumptions!$C$90,Capex!$C$28*Assumptions!$C$85,0) -> 0 | J27: =IF(J2=Assumptions!$C$90,Capex!$C$28*Assumptions!$C$85,0) -> 0 | ... AA27: =IF(AA2=Assumptions!$C$90,Capex!$C$28*Assumptions!$C$85,0) -> 0
B28: WDV depreciation (40%) | C28: =(C26+C27)*Assumptions!$C$84 -> 1092.4977 | D28: =(D26+D27)*Assumptions!$C$84 -> 655.49859 | E28: =(E26+E27)*Assumptions!$C$84 -> 393.29915 | F28: =(F26+F27)*Assumptions!$C$84 -> 235.97949 | G28: =(G26+G27)*Assumptions!$C$84 -> 141.5877 | H28: =(H26+H27)*Assumptions!$C$84 -> 84.952617 | I28: =(I26+I27)*Assumptions!$C$84 -> 50.97157 | J28: =(J26+J27)*Assumptions!$C$84 -> 30.582942 | ... AA28: =(AA26+AA27)*Assumptions!$C$84 -> 0.12577912
B29: WDV block — closing | C29: =C26+C27-C28 -> 1638.7465 | D29: =D26+D27-D28 -> 983.24789 | E29: =E26+E27-E28 -> 589.94873 | F29: =F26+F27-F28 -> 353.96924 | G29: =G26+G27-G28 -> 212.38154 | H29: =H26+H27-H28 -> 127.42893 | I29: =I26+I27-I28 -> 76.457356 | J29: =J26+J27-J28 -> 45.874413 | ... AA29: =AA26+AA27-AA28 -> 0.18866868
B30: SLM on non-eligible 5% | C30: =Capex!$C$21*(1-Assumptions!$C$85)/Assumptions!$C$86 -> 5.7499876 | D30: =Capex!$C$21*(1-Assumptions!$C$85)/Assumptions!$C$86 -> 5.7499876 | E30: =Capex!$C$21*(1-Assumptions!$C$85)/Assumptions!$C$86 -> 5.7499876 | F30: =Capex!$C$21*(1-Assumptions!$C$85)/Assumptions!$C$86 -> 5.7499876 | G30: =Capex!$C$21*(1-Assumptions!$C$85)/Assumptions!$C$86 -> 5.7499876 | H30: =Capex!$C$21*(1-Assumptions!$C$85)/Assumptions!$C$86 -> 5.7499876 | I30: =Capex!$C$21*(1-Assumptions!$C$85)/Assumptions!$C$86 -> 5.7499876 | J30: =Capex!$C$21*(1-Assumptions!$C$85)/Assumptions!$C$86 -> 5.7499876 | ... AA30: =Capex!$C$21*(1-Assumptions!$C$85)/Assumptions!$C$86 -> 5.7499876
B31: Total tax depreciation | C31: =C28+C30 -> 1098.2476 | D31: =D28+D30 -> 661.24858 | E31: =E28+E30 -> 399.04914 | F31: =F28+F30 -> 241.72948 | G31: =G28+G30 -> 147.33768 | H31: =H28+H30 -> 90.702605 | I31: =I28+I30 -> 56.721558 | J31: =J28+J30 -> 36.33293 | ... AA31: =AA28+AA30 -> 5.8757668
B32: Taxable income (EBITDA - interest - tax dep) | C32: =C23-C47-C31 -> -899.31259 | D32: =D23-D47-D31 -> -461.78431 | E32: =E23-E47-E31 -> -194.67536 | F32: =F23-F47-F31 -> -32.037461 | G32: =G23-G47-G31 -> 68.116662 | H32: =H23-H47-H31 -> 130.99659 | I32: =I23-I47-I31 -> 171.74681 | J32: =J23-J47-J31 -> 199.47436 | ... AA32: =AA23-AA47-AA31 -> 321.26155
B33: Loss brought forward | C33: =0 -> 0 | D33: =C36 -> 899.31259 | E33: =D36 -> 1361.0969 | F33: =E36 -> 1555.7723 | G33: =F36 -> 1587.8097 | H33: =G36 -> 1519.6931 | I33: =H36 -> 1388.6965 | J33: =I36 -> 1216.9496 | K33: =J36 -> 1017.4753 | ... AA33: =Z36 -> 0
B34: Taxable after loss set-off | C34: =C32-C33 -> -899.31259 | D34: =D32-D33 -> -1361.0969 | E34: =E32-E33 -> -1555.7723 | F34: =F32-F33 -> -1587.8097 | G34: =G32-G33 -> -1519.6931 | H34: =H32-H33 -> -1388.6965 | I34: =I32-I33 -> -1216.9496 | J34: =J32-J33 -> -1017.4753 | ... AA34: =AA32-AA33 -> 321.26155
B35: Tax payable | C35: =MAX(0,C34)*Assumptions!$C$83 -> 0 | D35: =MAX(0,D34)*Assumptions!$C$83 -> 0 | E35: =MAX(0,E34)*Assumptions!$C$83 -> 0 | F35: =MAX(0,F34)*Assumptions!$C$83 -> 0 | G35: =MAX(0,G34)*Assumptions!$C$83 -> 0 | H35: =MAX(0,H34)*Assumptions!$C$83 -> 0 | I35: =MAX(0,I34)*Assumptions!$C$83 -> 0 | J35: =MAX(0,J34)*Assumptions!$C$83 -> 0 | ... AA35: =MAX(0,AA34)*Assumptions!$C$83 -> 80.855108
B36: Loss carried forward | C36: =MAX(0,-C34) -> 899.31259 | D36: =MAX(0,-D34) -> 1361.0969 | E36: =MAX(0,-E34) -> 1555.7723 | F36: =MAX(0,-F34) -> 1587.8097 | G36: =MAX(0,-G34) -> 1519.6931 | H36: =MAX(0,-H34) -> 1388.6965 | I36: =MAX(0,-I34) -> 1216.9496 | J36: =MAX(0,-J34) -> 1017.4753 | ... AA36: =MAX(0,-AA34) -> 0
B38: PROFIT & LOSS
B39: Book depreciation (SLM to 5% residual) | C39: =Capex!$C$21*(1-Assumptions!$C$87)/Assumptions!$C$86 -> 109.24977 | D39: =Capex!$C$21*(1-Assumptions!$C$87)/Assumptions!$C$86 -> 109.24977 | E39: =Capex!$C$21*(1-Assumptions!$C$87)/Assumptions!$C$86 -> 109.24977 | F39: =Capex!$C$21*(1-Assumptions!$C$87)/Assumptions!$C$86 -> 109.24977 | G39: =Capex!$C$21*(1-Assumptions!$C$87)/Assumptions!$C$86 -> 109.24977 | H39: =Capex!$C$21*(1-Assumptions!$C$87)/Assumptions!$C$86 -> 109.24977 | I39: =Capex!$C$21*(1-Assumptions!$C$87)/Assumptions!$C$86 -> 109.24977 | J39: =Capex!$C$21*(1-Assumptions!$C$87)/Assumptions!$C$86 -> 109.24977 | ... L39: =Capex!$C$21*(1-Assumptions!$C$87)/Assumptions!$C$86 -> 109.24977 | M39: =Capex!$C$21*(1-Assumptions!$C$87)/Assumptions!$C$86+Capex!$C$28*(1-Assumptions!$C$87)/(25-Assumptions!$C$90+1) -> 134.89977 | N39: =Capex!$C$21*(1-Assumptions!$C$87)/Assumptions!$C$86+Capex!$C$28*(1-Assumptions!$C$87)/(25-Assumptions!$C$90+1) -> 134.89977 | O39: =Capex!$C$21*(1-Assumptions!$C$87)/Assumptions!$C$86+Capex!$C$28*(1-Assumptions!$C$87)/(25-Assumptions!$C$90+1) -> 134.89977 | P39: =Capex!$C$21*(1-Assumptions!$C$87)/Assumptions!$C$86+Capex!$C$28*(1-Assumptions!$C$87)/(25-Assumptions!$C$90+1) -> 134.89977 | Q39: =Capex!$C$21*(1-Assumptions!$C$87)/Assumptions!$C$86+Capex!$C$28*(1-Assumptions!$C$87)/(25-Assumptions!$C$90+1) -> 134.89977 | R39: =Capex!$C$21*(1-Assumptions!$C$87)/Assumptions!$C$86+Capex!$C$28*(1-Assumptions!$C$87)/(25-Assumptions!$C$90+1) -> 134.89977 | S39: =Capex!$C$21*(1-Assumptions!$C$87)/Assumptions!$C$86+Capex!$C$28*(1-Assumptions!$C$87)/(25-Assumptions!$C$90+1) -> 134.89977 | T39: =Capex!$C$21*(1-Assumptions!$C$87)/Assumptions!$C$86+Capex!$C$28*(1-Assumptions!$C$87)/(25-Assumptions!$C$90+1) -> 134.89977 | ... AA39: =Capex!$C$21*(1-Assumptions!$C$87)/Assumptions!$C$86+Capex!$C$28*(1-Assumptions!$C$87)/(25-Assumptions!$C$90+1) -> 134.89977
B40: EBIT | C40: =C23-C39 -> 278.35676 | D40: =D23-D39 -> 276.80463 | E40: =E23-E39 -> 275.18797 | F40: =F23-F39 -> 273.50457 | G40: =G23-G39 -> 271.75211 | H40: =H23-H39 -> 269.92822 | I40: =I23-I39 -> 268.03044 | J40: =J23-J39 -> 266.05624 | ... AA40: =AA23-AA39 -> 192.23755
B41: Interest on term debt | C41: =C47 -> 188.67147 | D41: =D47 -> 186.59012 | E41: =E47 -> 180.06396 | F41: =F47 -> 173.06231 | G41: =G47 -> 165.54753 | H41: =H47 -> 157.47879 | I41: =I47 -> 148.81184 | J41: =J47 -> 139.49871 | ... AA41: =AA47 -> 0
B42: Profit before tax | C42: =C40-C41 -> 89.685288 | D42: =D40-D41 -> 90.214509 | E42: =E40-E41 -> 95.124016 | F42: =F40-F41 -> 100.44225 | G42: =G40-G41 -> 106.20458 | H42: =H40-H41 -> 112.44943 | I42: =I40-I41 -> 119.2186 | J42: =J40-J41 -> 126.55753 | ... AA42: =AA40-AA41 -> 192.23755
B43: PAT | C43: =C42-C35 -> 89.685288 | D43: =D42-D35 -> 90.214509 | E43: =E42-E35 -> 95.124016 | F43: =F42-F35 -> 100.44225 | G43: =G42-G35 -> 106.20458 | H43: =H42-H35 -> 112.44943 | I43: =I42-I35 -> 119.2186 | J43: =J42-J35 -> 126.55753 | ... AA43: =AA42-AA35 -> 111.38245
B45: DEBT SCHEDULE (sculpted, constant DSCR)
B46: Debt — opening | C46: =Capex!$C$22 -> 2156.2454 | D46: =C51 -> 2132.4585 | E46: =D51 -> 2057.8738 | F46: =E51 -> 1977.855 | G46: =F51 -> 1891.9717 | H46: =G51 -> 1799.7575 | I46: =H51 -> 1700.7067 | J46: =I51 -> 1594.271 | K46: =J51 -> 1479.8558 | ... AA46: =Z51 -> 0
...

Sheet Tender Compliance
B1: Hard Tender Conditions & Optimized Output Validation
B3: HARD TENDER CONDITIONS (NHPC FDRE T-II) | C3: Model value | D3: Requirement | E3: Status | F3: Reference
B4: Monthly peak availability — minimum month (year 1) | C4: ='Monthly Y1'!F16 -> 0.9 | D4: =Assumptions!$C$24 -> 0.9 | E4: =IF('Monthly Y1'!F16>=Assumptions!$C$24,"PASS","FAIL") -> PASS | F4: RfS: 90% of contracted capacity across 4 daily peak hours, tested monthly
B5: All 12 months compliant (year 1) | C5: ='Monthly Y1'!K16 -> ALL PASS | D5: "ALL PASS" | E5: =IF('Monthly Y1'!K16="ALL PASS","PASS","FAIL") -> PASS | F5: Both peak and annual LDs can apply in the same year
B6: Annual CUF — minimum year | C6: =MIN('Dispatch 25Y'!I4:I28) -> 0.4 | D6: =Assumptions!$C$19*(1-Assumptions!$C$20) -> 0.34 | E6: =IF(MIN('Dispatch 25Y'!I4:I28)>=Assumptions!$C$19*(1-Assumptions!$C$20),"PASS","FAIL") -> PASS | F6: Floor: declared CUF - 15% (34%)
B7: Annual CUF — maximum year (offtake cap) | C7: =MAX('Dispatch 25Y'!I4:I28) -> 0.4 | D7: =Assumptions!$C$19*Assumptions!$C$21 -> 0.44 | E7: =IF(MAX('Dispatch 25Y'!I4:I28)<=Assumptions!$C$19*Assumptions!$C$21+0.0000001,"PASS","FAIL") -> PASS | F7: Cap: 110% of declared CUF (44%) — NHPC purchase limit
B8: Liquidated damages — total (year 1) | C8: ='Monthly Y1'!J16 -> 0 | D8: 0 | E8: =IF('Monthly Y1'!J16<=0.000001,"PASS","FAIL") -> PASS | F8: 1.5x tariff on shortfall energy
B9: Bid capacity >= minimum project size | C9: =Assumptions!$C$15 -> 200 | D9: 50 MW | E9: =IF(Assumptions!$C$15>=50,"PASS","FAIL") -> PASS | F9: RfS minimum 50 MW
B10: Bid capacity multiple of 10 MW | C10: =MOD(Assumptions!$C$15,10) -> 0 | D10: 0 | E10: =IF(MOD(Assumptions!$C$15,10)=0,"PASS","FAIL") -> PASS
B11: Bid capacity <= bidder cap | C11: =Assumptions!$C$15 -> 200 | D11: 600 MW | E11: =IF(Assumptions!$C$15<=600,"PASS","FAIL") -> PASS | F11: RfS maximum 600 MW per bidder
B12: BESS charging source | C12: "RE only" | D12: "RE only" | E12: "PASS" | F12: By construction: BESS charges only from co-located RE (no grid/fossil)
B13: Declared CUF >= 40% | C13: =Assumptions!$C$19 -> 0.4 | D13: 40% | E13: =IF(Assumptions!$C$19>=0.4,"PASS","FAIL") -> PASS | F13: RfS minimum declaration
B15: OPTIMIZED OUTPUT VALIDATION (model vs optimizer result) | C15: Optimizer | D15: This model | E15: Match
B16: Solar capacity (MW) | C16: 288.8 | D16: =Assumptions!$C$11 -> 288.8 | E16: =IF(ABS(C16-D16)<0.005,"MATCH","DIFF") -> MATCH
B17: Wind capacity (MW) | C17: 40.9 | D17: =Assumptions!$C$12 -> 40.9 | E17: =IF(ABS(C17-D17)<0.005,"MATCH","DIFF") -> MATCH
B18: BESS power (MW) | C18: 180 | D18: =Assumptions!$C$13 -> 180 | E18: =IF(ABS(C18-D18)<0.005,"MATCH","DIFF") -> MATCH
B19: BESS energy (MWh) | C19: 540 | D19: =Assumptions!$C$14 -> 540 | E19: =IF(ABS(C19-D19)<0.005,"MATCH","DIFF") -> MATCH
B20: Selected bid capacity (MW) | C20: 200 | D20: =Assumptions!$C$15 -> 200 | E20: =IF(ABS(C20-D20)<0.005,"MATCH","DIFF") -> MATCH
B21: Required tariff (Rs/kWh) — declared CUF 40% / 90% availability | C21: 5.9113 | D21: =Assumptions!$C$16 -> 5.9113 | E21: =IF(ABS(C21-D21)<0.005,"MATCH","DIFF") -> MATCH
B22: Equity IRR at bid tariff | C22: 0.14 | D22: ='Financial Model'!C68 -> 0.14000086 | E22: =IF(ABS(C22-D22)<0.001,"MATCH","DIFF") -> MATCH
B23: Min DSCR at bid tariff (>= floor) | C23: 1.1 | D23: ='Financial Model'!C70 -> 1.4782077 | E23: =IF(D23>=C23,"PASS","FAIL") -> PASS

Sheet Validation
B1: Validation — Excel formulas vs dispatch engine (calibrated reference run)
B2: Engine: fdre_enterprise_engine.py, seed 42, capacities as bid, delivery at declared CUF 40% / availability 90% (compliant, zero LD), tariff Rs 5.9113.
B4: Metric | C4: Engine | D4: This model | E4: Delta % | F4: Status
B5: Hard capex (cr) | C5: 2705.6081 | D5: =Capex!C15 -> 2705.6081 | E5: =IF(ABS(C5)>0.0001,(D5-C5)/ABS(C5),D5-C5) -> 0 | F5: =IF(ABS(E5)<0.005,"PASS","CHECK") -> PASS
B6: IDC (cr) | C6: 169.3857 | D6: =Capex!C20 -> 169.3857 | E6: =IF(ABS(C6)>0.0001,(D6-C6)/ABS(C6),D6-C6) -> -1.3303488e-09 | F6: =IF(ABS(E6)<0.005,"PASS","CHECK") -> PASS
B7: Total project cost (cr) | C7: 2874.9938 | D7: =Capex!C21 -> 2874.9938 | E7: =IF(ABS(C7)>0.0001,(D7-C7)/ABS(C7),D7-C7) -> -7.8380105e-11 | F7: =IF(ABS(E7)<0.005,"PASS","CHECK") -> PASS
B8: Debt (cr) | C8: 2156.2454 | D8: =Capex!C22 -> 2156.2454 | E8: =IF(ABS(C8)>0.0001,(D8-C8)/ABS(C8),D8-C8) -> 1.5350448e-10 | F8: =IF(ABS(E8)<0.005,"PASS","CHECK") -> PASS
B9: Equity (cr) | C9: 718.74846 | D9: =Capex!C23 -> 718.74846 | E9: =IF(ABS(C9)>0.0001,(D9-C9)/ABS(C9),D9-C9) -> 6.1727317e-10 | F9: =IF(ABS(E9)<0.005,"PASS","CHECK") -> PASS
B10: EMD (cr) | C10: 10 | D10: =Capex!C25 -> 10 | E10: =IF(ABS(C10)>0.0001,(D10-C10)/ABS(C10),D10-C10) -> 0 | F10: =IF(ABS(E10)<0.005,"PASS","CHECK") -> PASS
B11: PBG (cr) | C11: 145.806 | D11: =Capex!C26 -> 145.806 | E11: =IF(ABS(C11)>0.0001,(D11-C11)/ABS(C11),D11-C11) -> 0 | F11: =IF(ABS(E11)<0.005,"PASS","CHECK") -> PASS
B12: Year-1 PPA energy (MWh) | C12: 701280 | D12: ='Dispatch 25Y'!H4 -> 701280 | E12: =IF(ABS(C12)>0.0001,(D12-C12)/ABS(C12),D12-C12) -> 0 | F12: =IF(ABS(E12)<0.005,"PASS","CHECK") -> PASS
B13: Year-1 merchant energy (MWh) | C13: 105444.81 | D13: ='Dispatch 25Y'!K4 -> 105444.81 | E13: =IF(ABS(C13)>0.0001,(D13-C13)/ABS(C13),D13-C13) -> -2.438135e-12 | F13: =IF(ABS(E13)<0.005,"PASS","CHECK") -> PASS
B14: Year-1 total revenue (cr) | C14: 447.41465 | D14: ='Financial Model'!C13 -> 447.41465 | E14: =IF(ABS(C14)>0.0001,(D14-C14)/ABS(C14),D14-C14) -> -5.1514523e-10 | F14: =IF(ABS(E14)<0.005,"PASS","CHECK") -> PASS
B15: Year-1 total opex (cr) | C15: 59.808127 | D15: ='Financial Model'!C22 -> 59.808127 | E15: =IF(ABS(C15)>0.0001,(D15-C15)/ABS(C15),D15-C15) -> 2.5041837e-09 | F15: =IF(ABS(E15)<0.005,"PASS","CHECK") -> PASS
B16: Year-1 EBITDA (cr) | C16: 387.60652 | D16: ='Financial Model'!C23 -> 387.60652 | E16: =IF(ABS(C16)>0.0001,(D16-C16)/ABS(C16),D16-C16) -> -9.8103109e-10 | F16: =IF(ABS(E16)<0.005,"PASS","CHECK") -> PASS
B17: Year-1 CFADS (cr) | C17: 314.05891 | D17: ='Financial Model'!C55 -> 314.05891 | E17: =IF(ABS(C17)>0.0001,(D17-C17)/ABS(C17),D17-C17) -> -1.3053778e-10 | F17: =IF(ABS(E17)<0.005,"PASS","CHECK") -> PASS
B18: Year-1 FCFE (cr) | C18: 101.60054 | D18: ='Financial Model'!C57 -> 101.60056 | E18: =IF(ABS(C18)>0.0001,(D18-C18)/ABS(C18),D18-C18) -> 1.8597823e-07 | F18: =IF(ABS(E18)<0.005,"PASS","CHECK") -> PASS
B19: Year-14 tax (first tax-paying year, cr) | C19: 44.565529 | D19: ='Financial Model'!P35 -> 44.565463 | E19: =IF(ABS(C19)>0.0001,(D19-C19)/ABS(C19),D19-C19) -> -1.4803761e-06 | F19: =IF(ABS(E19)<0.005,"PASS","CHECK") -> PASS
B20: Year-11 augmentation (cr) | C20: 405 | D20: ='Financial Model'!M56 -> 405 | E20: =IF(ABS(C20)>0.0001,(D20-C20)/ABS(C20),D20-C20) -> 0 | F20: =IF(ABS(E20)<0.005,"PASS","CHECK") -> PASS
B21: Year-25 EBITDA (cr) | C21: 327.13732 | D21: ='Financial Model'!AA23 -> 327.13732 | E21: =IF(ABS(C21)>0.0001,(D21-C21)/ABS(C21),D21-C21) -> 2.5524458e-10 | F21: =IF(ABS(E21)<0.005,"PASS","CHECK") -> PASS
B22: Equity IRR | C22: 0.140001 | D22: ='Financial Model'!C68 -> 0.14000086 | E22: =IF(ABS(C22)>0.0001,(D22-C22)/ABS(C22),D22-C22) -> -9.9993313e-07 | F22: =IF(ABS(E22)<0.005,"PASS","CHECK") -> PASS
B23: Project IRR | C23: 0.100961 | D23: ='Financial Model'!C67 -> 0.10096057 | E23: =IF(ABS(C23)>0.0001,(D23-C23)/ABS(C23),D23-C23) -> -4.3048429e-06 | F23: =IF(ABS(E23)<0.005,"PASS","CHECK") -> PASS
B24: Min DSCR (x) | C24: 1.478214 | D24: ='Financial Model'!C70 -> 1.4782077 | E24: =IF(ABS(C24)>0.0001,(D24-C24)/ABS(C24),D24-C24) -> -4.2765995e-06 | F24: =IF(ABS(E24)<0.005,"PASS","CHECK") -> PASS
B25: Equity NPV @10% (cr) | C25: 257.39693 | D25: ='Financial Model'!C69 -> 257.39698 | E25: =IF(ABS(C25)>0.0001,(D25-C25)/ABS(C25),D25-C25) -> 1.7360921e-07 | F25: =IF(ABS(E25)<0.005,"PASS","CHECK") -> PASS
B27: PASS = within 0.5%. Engine values are hardcoded reference outputs from the calibrated run; model values are live formulas.
